Workbook

Sheet Actual
A1: Patient | B1: Diagnosis
A2: 1 | B2: 1
A3: 2 | B3: 0
A4: 3 | B4: 1
A5: 4 | B5: 0
A6: 5 | B6: 1
A7: 6 | B7: 1
A8: 7 | B8: 0
A9: 8 | B9: 0
A10: 9 | B10: 1
A11: 10 | B11: 1
A12: 11 | B12: 0
A13: 12 | B13: 0
... A64: 63 | B64: 0

Sheet Results
A1: CANCER STAGE
A2: PROMPT VARIATIONS | L2: SAME PROMPT
A3: Patient | B3: Actual Stage | C3: prompt1 | D3: prompt2 | E3: prompt3 | F3: prompt4 | G3: prompt5 | H3: Row accuracy | I3: Consensus rate | L3: Patient | M3: Actual Stage | N3: classify1 | O3: classify2 | P3: classify3 | Q3: classify4 | R3: classify5 | S3: Row accuracy | T3: Consensus rate
A4: 1 | B4: =Actual!$B2 -> 1 | C4: =prompt1!B2 -> 1 | D4: =prompt2!B2 -> 1 | E4: =prompt3!B2 -> 1 | F4: =prompt4!B2 -> 1 | G4: =prompt5!B2 -> 1 | H4: =COUNTIF($C4:$G4,$B4)/COLUMNS($C4:$G4) -> 1 | I4: =MAX(COUNTIF($C4:$G4,$C4),COUNTIF($C4:$G4,$D4),COUNTIF($C4:$G4,$E4),COUNTIF($C4:$G4,$F4),COUNTIF($C4:$G4,$G4)) / COLUMNS($C4:$G4) -> 1 | L4: 1 | M4: =Actual!$B2 -> 1 | N4: =classify1!B2 -> 1 | O4: =classify2!B2 -> 1 | P4: =classify3!B2 -> 1 | Q4: =classify4!B2 -> 1 | R4: =classify5!B2 -> 1 | S4: =COUNTIF($N4:$R4,$M4)/COLUMNS($N4:$R4) -> 1 | T4: =MAX(COUNTIF($N4:$R4,$N4),COUNTIF($N4:$R4,$O4),COUNTIF($N4:$R4,$P4),COUNTIF($N4:$R4,$Q4),COUNTIF($N4:$R4,$R4)) / COLUMNS($N4:$R4) -> 1
A5: =A4+1 -> 2 | B5: =Actual!$B3 -> 0 | C5: =prompt1!B3 -> 0 | D5: =prompt2!B3 -> 0 | E5: =prompt3!B3 -> 0 | F5: =prompt4!B3 -> 0 | G5: =prompt5!B3 -> 0 | H5: =COUNTIF($C5:$G5,$B5)/COLUMNS($C5:$G5) -> 1 | I5: =MAX(COUNTIF($C5:$G5,$C5),COUNTIF($C5:$G5,$D5),COUNTIF($C5:$G5,$E5),COUNTIF($C5:$G5,$F5),COUNTIF($C5:$G5,$G5)) / COLUMNS($C5:$G5) -> 1 | L5: =L4+1 -> 2 | M5: =Actual!$B3 -> 0 | N5: =classify1!B3 -> 0 | O5: =classify2!B3 -> 0 | P5: =classify3!B3 -> 0 | Q5: =classify4!B3 -> 0 | R5: =classify5!B3 -> 0 | S5: =COUNTIF($N5:$R5,$M5)/COLUMNS($N5:$R5) -> 1 | T5: =MAX(COUNTIF($N5:$R5,$N5),COUNTIF($N5:$R5,$O5),COUNTIF($N5:$R5,$P5),COUNTIF($N5:$R5,$Q5),COUNTIF($N5:$R5,$R5)) / COLUMNS($N5:$R5) -> 1
A6: =A5+1 -> 3 | B6: =Actual!$B4 -> 1 | C6: =prompt1!B4 -> 1 | D6: =prompt2!B4 -> 1 | E6: =prompt3!B4 -> 1 | F6: =prompt4!B4 -> 1 | G6: =prompt5!B4 -> 1 | H6: =COUNTIF($C6:$G6,$B6)/COLUMNS($C6:$G6) -> 1 | I6: =MAX(COUNTIF($C6:$G6,$C6),COUNTIF($C6:$G6,$D6),COUNTIF($C6:$G6,$E6),COUNTIF($C6:$G6,$F6),COUNTIF($C6:$G6,$G6)) / COLUMNS($C6:$G6) -> 1 | L6: =L5+1 -> 3 | M6: =Actual!$B4 -> 1 | N6: =classify1!B4 -> 1 | O6: =classify2!B4 -> 1 | P6: =classify3!B4 -> 1 | Q6: =classify4!B4 -> 1 | R6: =classify5!B4 -> 1 | S6: =COUNTIF($N6:$R6,$M6)/COLUMNS($N6:$R6) -> 1 | T6: =MAX(COUNTIF($N6:$R6,$N6),COUNTIF($N6:$R6,$O6),COUNTIF($N6:$R6,$P6),COUNTIF($N6:$R6,$Q6),COUNTIF($N6:$R6,$R6)) / COLUMNS($N6:$R6) -> 1
A7: =A6+1 -> 4 | B7: =Actual!$B5 -> 0 | C7: =prompt1!B5 -> 0 | D7: =prompt2!B5 -> 0 | E7: =prompt3!B5 -> 0 | F7: =prompt4!B5 -> 0 | G7: =prompt5!B5 -> 0 | H7: =COUNTIF($C7:$G7,$B7)/COLUMNS($C7:$G7) -> 1 | I7: =MAX(COUNTIF($C7:$G7,$C7),COUNTIF($C7:$G7,$D7),COUNTIF($C7:$G7,$E7),COUNTIF($C7:$G7,$F7),COUNTIF($C7:$G7,$G7)) / COLUMNS($C7:$G7) -> 1 | L7: =L6+1 -> 4 | M7: =Actual!$B5 -> 0 | N7: =classify1!B5 -> 0 | O7: =classify2!B5 -> 0 | P7: =classify3!B5 -> 0 | Q7: =classify4!B5 -> 0 | R7: =classify5!B5 -> 0 | S7: =COUNTIF($N7:$R7,$M7)/COLUMNS($N7:$R7) -> 1 | T7: =MAX(COUNTIF($N7:$R7,$N7),COUNTIF($N7:$R7,$O7),COUNTIF($N7:$R7,$P7),COUNTIF($N7:$R7,$Q7),COUNTIF($N7:$R7,$R7)) / COLUMNS($N7:$R7) -> 1
A8: =A7+1 -> 5 | B8: =Actual!$B6 -> 1 | C8: =prompt1!B6 -> 1 | D8: =prompt2!B6 -> 1 | E8: =prompt3!B6 -> 1 | F8: =prompt4!B6 -> 1 | G8: =prompt5!B6 -> 1 | H8: =COUNTIF($C8:$G8,$B8)/COLUMNS($C8:$G8) -> 1 | I8: =MAX(COUNTIF($C8:$G8,$C8),COUNTIF($C8:$G8,$D8),COUNTIF($C8:$G8,$E8),COUNTIF($C8:$G8,$F8),COUNTIF($C8:$G8,$G8)) / COLUMNS($C8:$G8) -> 1 | L8: =L7+1 -> 5 | M8: =Actual!$B6 -> 1 | N8: =classify1!B6 -> 1 | O8: =classify2!B6 -> 1 | P8: =classify3!B6 -> 1 | Q8: =classify4!B6 -> 1 | R8: =classify5!B6 -> 1 | S8: =COUNTIF($N8:$R8,$M8)/COLUMNS($N8:$R8) -> 1 | T8: =MAX(COUNTIF($N8:$R8,$N8),COUNTIF($N8:$R8,$O8),COUNTIF($N8:$R8,$P8),COUNTIF($N8:$R8,$Q8),COUNTIF($N8:$R8,$R8)) / COLUMNS($N8:$R8) -> 1
A9: =A8+1 -> 6 | B9: =Actual!$B7 -> 1 | C9: =prompt1!B7 -> 1 | D9: =prompt2!B7 -> 1 | E9: =prompt3!B7 -> 1 | F9: =prompt4!B7 -> 1 | G9: =prompt5!B7 -> 1 | H9: =COUNTIF($C9:$G9,$B9)/COLUMNS($C9:$G9) -> 1 | I9: =MAX(COUNTIF($C9:$G9,$C9),COUNTIF($C9:$G9,$D9),COUNTIF($C9:$G9,$E9),COUNTIF($C9:$G9,$F9),COUNTIF($C9:$G9,$G9)) / COLUMNS($C9:$G9) -> 1 | L9: =L8+1 -> 6 | M9: =Actual!$B7 -> 1 | N9: =classify1!B7 -> 1 | O9: =classify2!B7 -> 1 | P9: =classify3!B7 -> 1 | Q9: =classify4!B7 -> 1 | R9: =classify5!B7 -> 1 | S9: =COUNTIF($N9:$R9,$M9)/COLUMNS($N9:$R9) -> 1 | T9: =MAX(COUNTIF($N9:$R9,$N9),COUNTIF($N9:$R9,$O9),COUNTIF($N9:$R9,$P9),COUNTIF($N9:$R9,$Q9),COUNTIF($N9:$R9,$R9)) / COLUMNS($N9:$R9) -> 1
A10: =A9+1 -> 7 | B10: =Actual!$B8 -> 0 | C10: =prompt1!B8 -> 0 | D10: =prompt2!B8 -> 0 | E10: =prompt3!B8 -> 0 | F10: =prompt4!B8 -> 0 | G10: =prompt5!B8 -> 0 | H10: =COUNTIF($C10:$G10,$B10)/COLUMNS($C10:$G10) -> 1 | I10: =MAX(COUNTIF($C10:$G10,$C10),COUNTIF($C10:$G10,$D10),COUNTIF($C10:$G10,$E10),COUNTIF($C10:$G10,$F10),COUNTIF($C10:$G10,$G10)) / COLUMNS($C10:$G10) -> 1 | L10: =L9+1 -> 7 | M10: =Actual!$B8 -> 0 | N10: =classify1!B8 -> 0 | O10: =classify2!B8 -> 0 | P10: =classify3!B8 -> 0 | Q10: =classify4!B8 -> 0 | R10: =classify5!B8 -> 0 | S10: =COUNTIF($N10:$R10,$M10)/COLUMNS($N10:$R10) -> 1 | T10: =MAX(COUNTIF($N10:$R10,$N10),COUNTIF($N10:$R10,$O10),COUNTIF($N10:$R10,$P10),COUNTIF($N10:$R10,$Q10),COUNTIF($N10:$R10,$R10)) / COLUMNS($N10:$R10) -> 1
A11: =A10+1 -> 8 | B11: =Actual!$B9 -> 0 | C11: =prompt1!B9 -> 0 | D11: =prompt2!B9 -> 0 | E11: =prompt3!B9 -> 0 | F11: =prompt4!B9 -> 0 | G11: =prompt5!B9 -> 0 | H11: =COUNTIF($C11:$G11,$B11)/COLUMNS($C11:$G11) -> 1 | I11: =MAX(COUNTIF($C11:$G11,$C11),COUNTIF($C11:$G11,$D11),COUNTIF($C11:$G11,$E11),COUNTIF($C11:$G11,$F11),COUNTIF($C11:$G11,$G11)) / COLUMNS($C11:$G11) -> 1 | L11: =L10+1 -> 8 | M11: =Actual!$B9 -> 0 | N11: =classify1!B9 -> 0 | O11: =classify2!B9 -> 0 | P11: =classify3!B9 -> 0 | Q11: =classify4!B9 -> 0 | R11: =classify5!B9 -> 0 | S11: =COUNTIF($N11:$R11,$M11)/COLUMNS($N11:$R11) -> 1 | T11: =MAX(COUNTIF($N11:$R11,$N11),COUNTIF($N11:$R11,$O11),COUNTIF($N11:$R11,$P11),COUNTIF($N11:$R11,$Q11),COUNTIF($N11:$R11,$R11)) / COLUMNS($N11:$R11) -> 1
A12: =A11+1 -> 9 | B12: =Actual!$B10 -> 1 | C12: =prompt1!B10 -> 1 | D12: =prompt2!B10 -> 1 | E12: =prompt3!B10 -> 1 | F12: =prompt4!B10 -> 1 | G12: =prompt5!B10 -> 1 | H12: =COUNTIF($C12:$G12,$B12)/COLUMNS($C12:$G12) -> 1 | I12: =MAX(COUNTIF($C12:$G12,$C12),COUNTIF($C12:$G12,$D12),COUNTIF($C12:$G12,$E12),COUNTIF($C12:$G12,$F12),COUNTIF($C12:$G12,$G12)) / COLUMNS($C12:$G12) -> 1 | L12: =L11+1 -> 9 | M12: =Actual!$B10 -> 1 | N12: =classify1!B10 -> 1 | O12: =classify2!B10 -> 0 | P12: =classify3!B10 -> 1 | Q12: =classify4!B10 -> 1 | R12: =classify5!B10 -> 1 | S12: =COUNTIF($N12:$R12,$M12)/COLUMNS($N12:$R12) -> 0.8 | T12: =MAX(COUNTIF($N12:$R12,$N12),COUNTIF($N12:$R12,$O12),COUNTIF($N12:$R12,$P12),COUNTIF($N12:$R12,$Q12),COUNTIF($N12:$R12,$R12)) / COLUMNS($N12:$R12) -> 0.8
A13: =A12+1 -> 10 | B13: =Actual!$B11 -> 1 | C13: =prompt1!B11 -> 1 | D13: =prompt2!B11 -> 1 | E13: =prompt3!B11 -> 1 | F13: =prompt4!B11 -> 0 | G13: =prompt5!B11 -> 1 | H13: =COUNTIF($C13:$G13,$B13)/COLUMNS($C13:$G13) -> 0.8 | I13: =MAX(COUNTIF($C13:$G13,$C13),COUNTIF($C13:$G13,$D13),COUNTIF($C13:$G13,$E13),COUNTIF($C13:$G13,$F13),COUNTIF($C13:$G13,$G13)) / COLUMNS($C13:$G13) -> 0.8 | L13: =L12+1 -> 10 | M13: =Actual!$B11 -> 1 | N13: =classify1!B11 -> 1 | O13: =classify2!B11 -> 1 | P13: =classify3!B11 -> 1 | Q13: =classify4!B11 -> 0 | R13: =classify5!B11 -> 1 | S13: =COUNTIF($N13:$R13,$M13)/COLUMNS($N13:$R13) -> 0.8 | T13: =MAX(COUNTIF($N13:$R13,$N13),COUNTIF($N13:$R13,$O13),COUNTIF($N13:$R13,$P13),COUNTIF($N13:$R13,$Q13),COUNTIF($N13:$R13,$R13)) / COLUMNS($N13:$R13) -> 0.8
A14: =A13+1 -> 11 | B14: =Actual!$B12 -> 0 | C14: =prompt1!B12 -> 0 | D14: =prompt2!B12 -> 0 | E14: =prompt3!B12 -> 0 | F14: =prompt4!B12 -> 0 | G14: =prompt5!B12 -> 0 | H14: =COUNTIF($C14:$G14,$B14)/COLUMNS($C14:$G14) -> 1 | I14: =MAX(COUNTIF($C14:$G14,$C14),COUNTIF($C14:$G14,$D14),COUNTIF($C14:$G14,$E14),COUNTIF($C14:$G14,$F14),COUNTIF($C14:$G14,$G14)) / COLUMNS($C14:$G14) -> 1 | L14: =L13+1 -> 11 | M14: =Actual!$B12 -> 0 | N14: =classify1!B12 -> 0 | O14: =classify2!B12 -> 0 | P14: =classify3!B12 -> 0 | Q14: =classify4!B12 -> 0 | R14: =classify5!B12 -> 0 | S14: =COUNTIF($N14:$R14,$M14)/COLUMNS($N14:$R14) -> 1 | T14: =MAX(COUNTIF($N14:$R14,$N14),COUNTIF($N14:$R14,$O14),COUNTIF($N14:$R14,$P14),COUNTIF($N14:$R14,$Q14),COUNTIF($N14:$R14,$R14)) / COLUMNS($N14:$R14) -> 1
A15: =A14+1 -> 12 | B15: =Actual!$B13 -> 0 | C15: =prompt1!B13 -> 0 | D15: =prompt2!B13 -> 0 | E15: =prompt3!B13 -> 0 | F15: =prompt4!B13 -> 0 | G15: =prompt5!B13 -> 0 | H15: =COUNTIF($C15:$G15,$B15)/COLUMNS($C15:$G15) -> 1 | I15: =MAX(COUNTIF($C15:$G15,$C15),COUNTIF($C15:$G15,$D15),COUNTIF($C15:$G15,$E15),COUNTIF($C15:$G15,$F15),COUNTIF($C15:$G15,$G15)) / COLUMNS($C15:$G15) -> 1 | L15: =L14+1 -> 12 | M15: =Actual!$B13 -> 0 | N15: =classify1!B13 -> 0 | O15: =classify2!B13 -> 0 | P15: =classify3!B13 -> 0 | Q15: =classify4!B13 -> 0 | R15: =classify5!B13 -> 0 | S15: =COUNTIF($N15:$R15,$M15)/COLUMNS($N15:$R15) -> 1 | T15: =MAX(COUNTIF($N15:$R15,$N15),COUNTIF($N15:$R15,$O15),COUNTIF($N15:$R15,$P15),COUNTIF($N15:$R15,$Q15),COUNTIF($N15:$R15,$R15)) / COLUMNS($N15:$R15) -> 1
A16: =A15+1 -> 13 | B16: =Actual!$B14 -> 1 | C16: =prompt1!B14 -> 1 | D16: =prompt2!B14 -> 1 | E16: =prompt3!B14 -> 1 | F16: =prompt4!B14 -> 1 | G16: =prompt5!B14 -> 1 | H16: =COUNTIF($C16:$G16,$B16)/COLUMNS($C16:$G16) -> 1 | I16: =MAX(COUNTIF($C16:$G16,$C16),COUNTIF($C16:$G16,$D16),COUNTIF($C16:$G16,$E16),COUNTIF($C16:$G16,$F16),COUNTIF($C16:$G16,$G16)) / COLUMNS($C16:$G16) -> 1 | L16: =L15+1 -> 13 | M16: =Actual!$B14 -> 1 | N16: =classify1!B14 -> 1 | O16: =classify2!B14 -> 1 | P16: =classify3!B14 -> 1 | Q16: =classify4!B14 -> 1 | R16: =classify5!B14 -> 1 | S16: =COUNTIF($N16:$R16,$M16)/COLUMNS($N16:$R16) -> 1 | T16: =MAX(COUNTIF($N16:$R16,$N16),COUNTIF($N16:$R16,$O16),COUNTIF($N16:$R16,$P16),COUNTIF($N16:$R16,$Q16),COUNTIF($N16:$R16,$R16)) / COLUMNS($N16:$R16) -> 1
... A66: =A65+1 -> 63 | B66: =Actual!$B64 -> 0 | C66: =prompt1!B64 -> 1 | D66: =prompt2!B64 -> 1 | E66: =prompt3!B64 -> 1 | F66: =prompt4!B64 -> 1 | G66: =prompt5!B64 -> 1 | H66: =COUNTIF($C66:$G66,$B66)/COLUMNS($C66:$G66) -> 0 | I66: =MAX(COUNTIF($C66:$G66,$C66),COUNTIF($C66:$G66,$D66),COUNTIF($C66:$G66,$E66),COUNTIF($C66:$G66,$F66),COUNTIF($C66:$G66,$G66)) / COLUMNS($C66:$G66) -> 1 | L66: =L65+1 -> 63 | M66: =Actual!$B64 -> 0 | N66: =classify1!B64 -> 1 | O66: =classify2!B64 -> 1 | P66: =classify3!B64 -> 1 | Q66: =classify4!B64 -> 1 | R66: =classify5!B64 -> 1 | S66: =COUNTIF($N66:$R66,$M66)/COLUMNS($N66:$R66) -> 0 | T66: =MAX(COUNTIF($N66:$R66,$N66),COUNTIF($N66:$R66,$O66),COUNTIF($N66:$R66,$P66),COUNTIF($N66:$R66,$Q66),COUNTIF($N66:$R66,$R66)) / COLUMNS($N66:$R66) -> 1
B67: AVG accuracy | C67: {=SUMPRODUCT(--(C4:C66=B4:B66)) / COUNTA(B4:B66)} -> 0.82539683 | D67: {=SUMPRODUCT(--(D4:D66=B4:B66)) / COUNTA(B4:B66)} -> 0.85714286 | E67: {=SUMPRODUCT(--(E4:E66=B4:B66)) / COUNTA(B4:B66)} -> 0.84126984 | F67: {=SUMPRODUCT(--(F4:F66=B4:B66)) / COUNTA(B4:B66)} -> 0.80952381 | G67: {=SUMPRODUCT(--(G4:G66=B4:B66)) / COUNTA(B4:B66)} -> 0.82539683 | H67: =AVERAGE(H4:H66) -> 0.83174603 | I67: =AVERAGE(I4:J66) -> 0.98730159 | M67: AVG accuracy | N67: {=SUMPRODUCT(--(N4:N66=M4:M66)) / COUNTA(M4:M66)} -> 0.82539683 | O67: {=SUMPRODUCT(--(O4:O66=M4:M66)) / COUNTA(M4:M66)} -> 0.79365079 | P67: {=SUMPRODUCT(--(P4:P66=M4:M66)) / COUNTA(M4:M66)} -> 0.82539683 | Q67: {=SUMPRODUCT(--(Q4:Q66=M4:M66)) / COUNTA(M4:M66)} -> 0.82539683 | R67: {=SUMPRODUCT(--(R4:R66=M4:M66)) / COUNTA(M4:M66)} -> 0.82539683 | S67: =AVERAGE(S4:S66) -> 0.81904762 | T67: =AVERAGE(T4:T66) -> 0.98730159

Sheet prompt1
A1: Patient | B1: cancer_prediction | C1: confidence | D1: reasoning
A2: 1 | B2: 1 | C2: 96 | D2: CA19-9 is markedly elevated (422), which strongly supports pancreatic malignancy in the appropriate clinical context. The accompanying pancreatic-associated protein markers (LYVE1, REG1B, and TFF1) are also elevated, reinforcing a cancer signal rather than a benign condition. Overall biomarker pattern is highly consistent with pancreatic cancer.
A3: 2 | B3: 0 | C3: 86 | D3: CA19-9 is low/within normal range (30), which argues against pancreatic cancer. The other markers (LYVE1 very low, REG1B modest, TFF1 elevated) do not form a strong pancreatic-cancer pattern without a CA19-9 rise; overall biomarker profile is more consistent with non-malignant/pancreatic inflammation-related changes than cancer.
A4: 3 | B4: 1 | C4: 99 | D4: CA19-9 is extremely elevated (11740), far above typical benign elevations and highly suggestive of pancreatic malignancy in this evaluation context. Additional pancreatic-associated markers (REG1B, TFF1, LYVE1) are also markedly elevated, supporting a cancer profile. Normal creatinine reduces the likelihood that CA19-9 is falsely elevated due to renal impairment.
A5: 4 | B5: 0 | C5: 92 | D5: CA19-9 is very low/normal (6.71), which argues strongly against pancreatic cancer. The additional markers provided (LYVE1, REG1A/REG1B, TFF1) do not show a pattern that outweighs the low CA19-9; creatinine is low and unlikely to be falsely elevating tumor markers. Overall biomarker profile is more consistent with no pancreatic cancer.
A6: 5 | B6: 1 | C6: 97 | D6: CA19-9 is extremely elevated (1621), which is highly suggestive of pancreatic malignancy in the appropriate clinical context. Although creatinine is markedly high (renal dysfunction can increase CA19-9), the magnitude of elevation plus an age typical for pancreatic cancer supports cancer as the most likely explanation. The additional protein markers (elevated TFF1/REG family) are also more consistent with pancreatic tumor-associated signatures than with a purely benign process.
A7: 6 | B7: 1 | C7: 96 | D7: CA19-9 is markedly elevated (538), which is strongly suggestive of pancreatic malignancy in this age group. The associated biomarker panel shows very high TFF1 and elevated REG1B/REG1A, a pattern consistent with pancreatic cancer rather than benign disease. Normal creatinine reduces the likelihood that CA19-9 is falsely elevated from renal impairment.
A8: 7 | B8: 0 | C8: 92 | D8: CA19-9 is very low (6.9), which argues strongly against pancreatic cancer in a typical secretor. Other provided biomarkers do not show a clear malignant pattern sufficient to outweigh the low CA19-9, and renal function (creatinine ~0.95) is normal, reducing concern for CA19-9 distortion from kidney impairment. Overall profile is more consistent with non-cancer.
A9: 8 | B9: 0 | C9: 71 | D9: CA19-9 is within/near normal range (~31 U/mL; typically concerning when clearly elevated, e.g., >37 and especially much higher). Creatinine is normal, reducing concern for renal-related marker distortion. Although LYVE1/REG1B/TFF1 show some elevation, the absence of a clearly elevated CA19-9 makes pancreatic cancer less likely overall in this profile.
A10: 9 | B10: 1 | C10: 86 | D10: CA19-9 is markedly elevated (468), which is strongly suspicious for pancreatic malignancy. The supporting protein biomarkers are also very high (notably TFF1 ~2207 and elevated REG1A/REG1B), a pattern more consistent with pancreatic cancer-associated signatures than benign disease. Although the patient is young and creatinine is very high (which can confound CA19-9), the magnitude and multi-marker concordance still favor cancer.
A11: 10 | B11: 1 | C11: 72 | D11: CA19-9 is elevated (66; above typical 37 cutoff) and there is a strongly abnormal multi-marker pattern with very high TFF1 and elevated REG1B/REG1A, which together are more consistent with pancreatic malignancy than benign disease. Creatinine is normal, making a renal-related artifact less likely.
A12: 11 | B12: 0 | C12: 74 | D12: CA19-9 is only mildly elevated (50) and can rise with benign biliary/inflammatory conditions; age is relatively young for pancreatic cancer. The protein markers (LYVE1, REG1B, TFF1, REG1A) do not show a strongly cancer-typical pattern with markedly elevated CA19-9, and creatinine is normal, reducing concern for confounding renal retention. Overall profile is more consistent with non-malignant or low-likelihood disease than pancreatic cancer.
A13: 12 | B13: 0 | C13: 78 | D13: CA19-9 is low/within normal range (22), which argues against pancreatic cancer. Creatinine is normal, reducing concern for CA19-9 distortion from renal dysfunction. Although REG1B/TFF1 appear elevated, in the setting of a normal CA19-9 and no other supportive clinical signals, the overall biomarker pattern is more consistent with non-malignant pancreatic/inflammatory changes than cancer.
... A64: 63 | B64: 1 | C64: 78 | D64: CA19-9 is clearly elevated (114.8), which supports pancreatic malignancy in the right context. In addition, multiple pancreatic-associated protein biomarkers (REG1B, TFF1, LYVE1) are markedly elevated, a pattern more consistent with pancreatic cancer signatures than with normal findings. Creatinine is elevated but does not by itself explain the combined strong multi-marker elevation.

Sheet prompt2
A1: Patient | B1: cancer_prediction | C1: confidence | D1: reasoning
A2: 1 | B2: 1 | C2: 93 | D2: CA19-9 is markedly elevated (422), which strongly supports pancreatic malignancy in this clinical context. The accompanying biomarker pattern (elevated LYVE1, REG1B, and very high TFF1) is more consistent with pancreatic cancer–associated signatures than with a benign process, making cancer likely.
A3: 2 | B3: 0 | C3: 78 | D3: CA19-9 is low/normal (30) and not suggestive of pancreatic cancer. The other biomarkers do not show a strongly malignant pattern; REG1B is only modestly elevated and REG1A is 0, which is not supportive of pancreatic cancer. Overall profile is more consistent with non-cancer.
A4: 3 | B4: 1 | C4: 99 | D4: CA19-9 is extremely elevated (11740), far above levels typically seen in benign conditions, strongly indicating pancreatic malignancy. Age (66) supports higher baseline risk, creatinine is normal (less likelihood of false elevation from renal impairment), and the associated protein biomarker pattern (elevated LYVE1/REG1B/TFF1) is consistent with pancreatic cancer signatures.
A5: 4 | B5: 0 | C5: 92 | D5: CA19-9 is very low (6.71), which argues strongly against pancreatic cancer. The other provided biomarkers do not show a pattern suggesting malignancy in the absence of CA19-9 elevation, and there are no clinical red flags in the record to offset this.
A6: 5 | B6: 1 | C6: 97 | D6: CA19-9 is extremely elevated (1621), a level strongly suggestive of pancreatic malignancy in the appropriate clinical context. While creatinine is markedly high and can confound CA19-9, the accompanying cancer-associated protein pattern (notably very high TFF1 along with elevated REG1B/REG1A and LYVE1) supports a pancreatic cancer signature rather than isolated renal-related CA19-9 elevation.
A7: 6 | B7: 1 | C7: 93 | D7: CA19-9 is markedly elevated (538), which is strongly suggestive of pancreatic malignancy in the appropriate clinical context. Additional pancreatic cancer–associated protein biomarkers (notably very high TFF1 and elevated REG1B/REG1A patterns) support a malignant process rather than benign disease, and creatinine is normal so CA19-9 elevation is less likely due to renal impairment.
A8: 7 | B8: 0 | C8: 90 | D8: CA19-9 is very low (6.9), which is not suggestive of pancreatic cancer in the absence of other strong indicators. Creatinine is normal, reducing concern for CA19-9 distortion from renal dysfunction. The additional biomarkers (LYVE1, REG1B, TFF1, REG1A) do not show a clearly malignant pattern here, so overall findings are more consistent with no pancreatic cancer.
A9: 8 | B9: 0 | C9: 66 | D9: CA19-9 is within the normal range (~<37), which lowers suspicion for pancreatic cancer. Creatinine is normal, reducing concern for spurious CA19-9 elevation from renal dysfunction. While REG1B and TFF1 appear elevated, the overall profile (especially non-elevated CA19-9) is more consistent with non-malignant pancreatic/inflammatory changes than pancreatic cancer.
A10: 9 | B10: 1 | C10: 92 | D10: CA19-9 is markedly elevated (468.3), which is strongly suggestive of pancreatic malignancy in the appropriate clinical context. The accompanying panel markers (very high REG1B and elevated TFF1/REG1A) are consistent with a pancreatic cancer-associated biomarker signature. Although creatinine is very high (renal dysfunction can inflate CA19-9), the magnitude and multi-marker elevation together still favor pancreatic cancer.
A11: 10 | B11: 1 | C11: 74 | D11: CA19-9 is elevated (66) above typical normal range, and the pancreatic biomarker panel shows markedly high TFF1 and elevated REG1B/LYVE1, a pattern more consistent with pancreatic malignancy than benign disease; creatinine is normal so CA19-9 is less likely falsely elevated from renal impairment.
A12: 11 | B12: 0 | C12: 72 | D12: CA19-9 is only mildly elevated (50) and can rise in benign biliary/inflammatory conditions; creatinine is normal, reducing concern for spurious CA19-9 elevation. The additional protein markers (LYVE1, REG1B, TFF1) are not strikingly high and REG1A is within a range more consistent with non-malignant pancreatic/inflammatory patterns than pancreatic cancer.
A13: 12 | B13: 0 | C13: 78 | D13: CA19-9 is low/within typical non-cancer range (~22), which argues against pancreatic cancer. Creatinine is normal so CA19-9 is unlikely to be falsely altered by renal dysfunction. While LYVE1/REG1B/TFF1 are present, the strongest standard clinical marker here (CA19-9) does not support malignancy, making cancer less likely overall.
... A64: 63 | B64: 1 | C64: 72 | D64: CA19-9 is clearly elevated (114.8), which is suspicious for pancreatic malignancy in the right context. The biomarker panel shows markedly high REG1B and TFF1 (and elevated LYVE1), a pattern more consistent with pancreatic cancer–associated signatures than with normal findings. Although creatinine is elevated (possible renal impairment that can confound tumor markers), the combined elevation across multiple pancreatic cancer–linked markers supports likely cancer.

Sheet prompt3
A1: Patient | B1: cancer_prediction | C1: confidence | D1: reasoning
A2: 1 | B2: 1 | C2: 96 | D2: CA19-9 is markedly elevated (422), which strongly supports pancreatic malignancy in this evaluation context. Age 68 increases baseline risk, and the accompanying biomarker pattern with elevated LYVE1/REG1B/TFF1 is consistent with pancreatic cancer-associated signatures rather than benign disease.
A3: 2 | B3: 0 | C3: 76 | D3: CA19-9 is low/near-normal (30), which argues against pancreatic cancer in most cases. The additional markers do not show a strong malignant pattern: LYVE1 is very low, REG1B is only mildly elevated, REG1A is absent, and while TFF1 is elevated it is nonspecific and can rise with benign/inflammatory GI conditions. Overall biomarker profile is more consistent with no pancreatic cancer.
A4: 3 | B4: 1 | C4: 99 | D4: CA19-9 is extremely elevated (11740), far above typical benign or cholestatic ranges, strongly suggesting pancreatic malignancy. Age 66 increases baseline risk. Creatinine is normal, making renal retention an unlikely cause of marker elevation. The accompanying biomarker pattern (elevated LYVE1/REG1B/TFF1) is also consistent with a pancreatic cancer signature.
A5: 4 | B5: 0 | C5: 87 | D5: CA19-9 is very low (6.71), which argues strongly against pancreatic cancer. LYVE1 is also very low, and while REG1B and TFF1 are elevated, these markers can rise with non-malignant pancreatic/inflammatory conditions; without CA19-9 elevation the overall pattern is more consistent with no pancreatic cancer.
A6: 5 | B6: 1 | C6: 92 | D6: CA19-9 is extremely elevated (1621), which is strongly suggestive of pancreatic malignancy in the appropriate clinical context. Although creatinine is markedly high (renal dysfunction can inflate CA19-9), the level is far above typical benign/renal-related elevations, and the accompanying biomarker pattern (notably very high TFF1 with elevated REG family markers) supports a pancreatic cancer signal rather than a purely non-malignant cause.
A7: 6 | B7: 1 | C7: 96 | D7: CA19-9 is markedly elevated (538), strongly suggestive of pancreatic malignancy in the right clinical context. Additional pancreas-associated markers (REG1B and very high TFF1) are also elevated, reinforcing a cancer-associated biomarker pattern rather than benign disease; creatinine is normal, making nonspecific elevation from renal impairment less likely.
A8: 7 | B8: 0 | C8: 84 | D8: CA19-9 is very low (6.9; not suggestive of pancreatic cancer). Creatinine is normal, reducing concern for biomarker distortion from renal dysfunction. The additional protein markers (LYVE1, REG1B, TFF1, REG1A) do not show a pattern strongly indicative of malignancy, so overall findings favor no pancreatic cancer.
A9: 8 | B9: 0 | C9: 72 | D9: CA19-9 is 31.24, within the typical normal range (<~37) and not suggestive of pancreatic cancer. Creatinine is normal, reducing concern for biomarker distortion from renal dysfunction. While REG1B and TFF1 appear elevated, without a concomitant CA19-9 rise or other strong malignant-pattern signals, this profile is more consistent with non-cancerous pancreatic/inflammatory changes than pancreatic cancer.
A10: 9 | B10: 1 | C10: 88 | D10: CA19-9 is markedly elevated (468.3), which is strongly suggestive of pancreatic malignancy in the right clinical context. The additional protein biomarkers (elevated TFF1 and REG family markers) are also more consistent with pancreatic cancer-associated signatures than with normal findings. Although young age and very high creatinine (which can confound CA19-9) reduce certainty, the overall biomarker pattern remains highly suspicious for pancreatic cancer.
A11: 10 | B11: 1 | C11: 72 | D11: CA19-9 is elevated (66; above typical normal cutoff ~37), and the pancreatic protein markers REG1B and especially TFF1 are markedly high, a pattern more consistent with pancreatic malignancy than normal/benign states. Creatinine is normal, reducing the likelihood of a false CA19-9 elevation from renal impairment.
A12: 11 | B12: 0 | C12: 68 | D12: CA19-9 is only mildly elevated (50) and can rise with benign biliary/inflammatory conditions; creatinine is normal, reducing concern for non-specific elevation. The protein panel pattern is not strongly suggestive of pancreatic cancer (REG1A low/near-normal and no clear marked elevation trend across LYVE1/REG1B/TFF1 consistent with PDAC), so overall cancer is less likely.
A13: 12 | B13: 0 | C13: 72 | D13: CA19-9 is low/within typical reference range (22), which argues against pancreatic cancer. Creatinine is normal, reducing concern for CA19-9 distortion from renal dysfunction. Although REG1B and TFF1 appear elevated, without an accompanying CA19-9 rise and with modest LYVE1, the overall biomarker pattern is more consistent with non-malignant pancreatic/inflammatory changes than cancer.
... A64: 63 | B64: 1 | C64: 76 | D64: CA19-9 is clearly elevated (~115; above typical normal <37), which raises suspicion for pancreatic malignancy. REG1B and TFF1 are also elevated patterns seen with pancreatic cancer signatures. Although creatinine is high (can confound CA19-9 via reduced clearance) and age is relatively young, the combined biomarker profile is more consistent with cancer than benign disease.

Sheet prompt4
A1: Patient | B1: cancer_prediction | C1: confidence | D1: reasoning
A2: 1 | B2: 1 | C2: 97 | D2: CA19-9 is markedly elevated (422), which strongly favors pancreatic malignancy in this evaluation context. Age (68) increases baseline risk, and the accompanying biomarker profile (very high TFF1 with elevated REG1B/LYVE1) is consistent with a pancreatic cancer-associated signature rather than a low-risk/normal pattern.
A3: 2 | B3: 0 | C3: 83 | D3: CA19-9 is low/near-normal (30), which does not support pancreatic cancer. Other markers are not strongly suggestive: LYVE1 is very low, REG1B is only mildly elevated, and REG1A is 0. Overall biomarker pattern lacks the typical elevation profile seen in pancreatic cancer.
A4: 3 | B4: 1 | C4: 99 | D4: CA19-9 is extremely elevated (11740), far above levels typically seen in benign conditions; age is in a high-risk range, creatinine is normal (less risk of false elevation), and the panel markers (LYVE1, REG1B, TFF1, REG1A) are collectively elevated in a pattern consistent with pancreatic malignancy.
A5: 4 | B5: 0 | C5: 84 | D5: CA19-9 is very low (6.71), which argues strongly against pancreatic cancer in this context. The other markers (LYVE1 very low; REG1A modest; REG1B/TFF1 elevated but can be increased in benign pancreatic/inflammatory conditions) do not outweigh the strongly non-malignant CA19-9 signal.
A6: 5 | B6: 1 | C6: 96 | D6: CA19-9 is extremely elevated (1621), far above typical benign ranges and strongly suggestive of pancreatic malignancy in this evaluation context. Although creatinine is markedly high (renal dysfunction can inflate CA19-9), the magnitude of elevation plus markedly abnormal associated protein biomarkers (very high TFF1/REG1B and elevated REG1A/LYVE1) supports pancreatic cancer being likely.
A7: 6 | B7: 1 | C7: 97 | D7: CA19-9 is markedly elevated (538), which strongly supports pancreatic malignancy in the appropriate clinical context. The accompanying biomarker pattern (elevated LYVE1, REG1B, and very high TFF1) is consistent with pancreatic cancer–associated signatures rather than a benign state, and creatinine is normal (less likely that renal impairment is inflating markers).
A8: 7 | B8: 0 | C8: 86 | D8: CA19-9 is very low (6.9), which argues strongly against pancreatic cancer. Creatinine is normal, reducing concern for biomarker distortion from renal dysfunction. The additional markers (LYVE1, REG1B, TFF1, REG1A) do not show a pattern strongly suggestive of malignancy in the absence of CA19-9 elevation, so overall cancer is unlikely.
A9: 8 | B9: 0 | C9: 78 | D9: CA19-9 is within the typical normal range (<37), which lowers likelihood of pancreatic cancer. Creatinine is normal, reducing concern for renal-related marker distortion. Although LYVE1/REG1B/TFF1 appear elevated, the combination without an elevated CA19-9 is more consistent with benign pancreatic/inflammatory changes than malignancy.
A10: 9 | B10: 1 | C10: 83 | D10: CA19-9 is markedly elevated (468), which is strongly associated with pancreatic malignancy. The panel markers (very high REG1B and elevated TFF1/REG1A) further support a cancer-like signature rather than normal. Although the patient is young and creatinine is very high (renal dysfunction can inflate CA19-9), the overall biomarker pattern remains more consistent with pancreatic cancer than benign disease.
A11: 10 | B11: 0 | C11: 62 | D11: CA19-9 is only mildly elevated (66) and can rise with benign biliary/inflammatory conditions; creatinine is normal, reducing concern for renal-related marker distortion. The protein markers (LYVE1/REG1A/REG1B/TFF1) do not show a pattern strongly suggestive of pancreatic cancer in this record, so overall findings are more consistent with non-malignant causes than active pancreatic cancer.
A12: 11 | B12: 0 | C12: 62 | D12: CA19-9 is only mildly elevated (50) and can rise with benign biliary/pancreatic inflammation; age is relatively young for pancreatic cancer. Creatinine is normal, and the provided protein markers do not show a pattern strongly suggestive of malignancy. Overall profile favors non-cancer over cancer.
A13: 12 | B13: 0 | C13: 84 | D13: CA19-9 is low/within typical non-cancer range (~22), which argues against pancreatic cancer. Kidney function (creatinine ~0.89) is normal so CA19-9 is not falsely lowered/altered by renal issues. Although LYVE1/REG1B/TFF1 are present, the overall profile is not strongly suggestive of malignancy without an elevated CA19-9 or other high-risk clinical features.
... A64: 63 | B64: 1 | C64: 78 | D64: CA19-9 is elevated (114.8; above typical ~37 cutoff), which supports pancreatic malignancy in the right clinical context. The panel markers (LYVE1/REG1B/TFF1) are also markedly high, consistent with a cancer-associated biomarker pattern rather than normal variation. While creatinine is elevated (140) and can confound some labs, it does not adequately explain the combination of elevated CA19-9 with strongly abnormal cancer-panel proteins.

Sheet prompt5
A1: Patient | B1: cancer_prediction | C1: confidence | D1: reasoning
A2: 1 | B2: 1 | C2: 96 | D2: CA19-9 is markedly elevated (422), which is strongly associated with pancreatic adenocarcinoma in this clinical context. Supporting protein biomarkers (LYVE1, REG1B, TFF1) are also elevated in patterns seen with pancreatic malignancy/pancreatic ductal disease. No alternative explanation is evident from the provided data.
A3: 2 | B3: 0 | C3: 78 | D3: CA19-9 is low/near-normal (30), which argues against pancreatic cancer. Other markers do not show a strongly malignant pattern: LYVE1 is very low, REG1B is only mildly elevated, and REG1A is absent; these findings are more consistent with non-cancer/inflammatory variation than pancreatic cancer. Overall biomarker profile does not support cancer.
A4: 3 | B4: 1 | C4: 99 | D4: CA19-9 is extremely elevated (11740), far above levels typically seen in benign pancreatic/biliary conditions and strongly suggestive of pancreatic malignancy. Age (66) increases baseline risk, and the accompanying abnormal protein biomarker profile (elevated LYVE1/REG1B/TFF1/REG1A pattern) is consistent with pancreatic cancer signatures. Normal creatinine reduces concern that renal impairment is falsely inflating markers.
A5: 4 | B5: 0 | C5: 84 | D5: CA19-9 is very low (6.71), which is not suggestive of pancreatic cancer. Additional biomarkers (LYVE1, REG1A/B, TFF1) do not show a pattern of markedly elevated tumor-associated signal that would outweigh the normal CA19-9. Overall profile is more consistent with no pancreatic cancer.
A6: 5 | B6: 1 | C6: 96 | D6: CA19-9 is extremely elevated (1621), a level strongly suggestive of pancreatic malignancy in the appropriate clinical context. Although creatinine is markedly high and can contribute to CA19-9 elevation, the magnitude remains highly concerning. The accompanying biomarker pattern (notably very high TFF1 with elevated REG family markers/LYVE1) is consistent with a pancreatic cancer-associated signature rather than benign disease alone.
A7: 6 | B7: 1 | C7: 95 | D7: CA19-9 is markedly elevated (538), far above typical benign ranges and strongly suggestive of pancreatic malignancy, especially in an older patient. The accompanying proteomic markers (notably very high TFF1 and elevated REG1B/REG1A/LYVE1 patterns) are consistent with a pancreatic cancer biomarker signature rather than isolated non-malignant variation. Normal creatinine reduces the likelihood that CA19-9 is falsely elevated due to renal impairment.
A8: 7 | B8: 0 | C8: 86 | D8: CA19-9 is very low (6.9) and not suggestive of pancreatic cancer. Creatinine is normal, reducing concern for renal-related CA19-9 distortion. The additional markers (LYVE1, REG1B, TFF1) do not show a clear high-risk pattern here, and REG1A is not markedly elevated. Overall biomarker profile favors no pancreatic cancer.
A9: 8 | B9: 0 | C9: 72 | D9: CA19-9 is within the normal/low range (~31), which argues against pancreatic cancer in the absence of a clear elevation. Creatinine is normal, reducing concern for falsely altered marker handling. While some pancreatic-associated proteins (e.g., REG1B/TFF1/LYVE1) are present, the overall pattern lacks a strong malignant signal compared with typical cancer cases where CA19-9 and multiple markers are markedly elevated.
A10: 9 | B10: 1 | C10: 88 | D10: CA19-9 is markedly elevated (468.3), which is strongly suspicious for pancreatic malignancy. The pancreatic-associated markers REG1B and TFF1 are also very high, supporting a cancer signal rather than benign variation. Although creatinine is severely elevated (possible renal dysfunction can inflate CA19-9), the concurrent strong elevation of multiple pancreatic biomarkers makes pancreatic cancer more likely than not.
A11: 10 | B11: 1 | C11: 78 | D11: CA19-9 is elevated (66, above typical normal ~<37), supporting pancreatic malignancy risk. In addition, pancreatic cancer–associated protein markers show markedly high levels (notably very high TFF1 with elevated REG1B/REG1A and LYVE1), a pattern more consistent with pancreatic cancer than benign conditions. Creatinine is normal, making renal-related marker elevation less likely.
A12: 11 | B12: 0 | C12: 64 | D12: CA19-9 is only mildly elevated (50) and can rise with benign pancreatic/biliary inflammation; creatinine is normal (reducing false CA19-9 elevation concerns). The protein markers shown (LYVE1/TFF1/REG1B) are not markedly high in a pattern strongly suggestive of pancreatic cancer, and age 48 is below the typical peak incidence. Overall biomarker profile is more consistent with non-malignant disease than pancreatic cancer.
A13: 12 | B13: 0 | C13: 83 | D13: CA19-9 is low/within normal range (22), which argues against pancreatic cancer. Creatinine is normal, reducing concern for CA19-9 distortion from renal impairment. The other markers (LYVE1, REG1B, TFF1, REG1A) do not show a clear malignant pattern in the absence of an elevated CA19-9, so overall cancer is unlikely.
... A64: 63 | B64: 1 | C64: 78 | D64: CA19-9 is elevated (114.8; above typical upper limit ~37), supporting pancreatic malignancy risk. Adjunct markers (LYVE1, REG1B, TFF1) are also markedly elevated, a pattern more consistent with pancreatic cancer biomarker panels than benign disease. Creatinine is elevated, which can confound CA19-9 somewhat, but the combined biomarker profile still favors cancer.

Sheet classify1
A1: Patient | B1: cancer_prediction | C1: confidence | D1: reasoning
A2: 1 | B2: 1 | C2: 96 | D2: CA19-9 is markedly elevated (422), which strongly supports pancreatic malignancy in the appropriate clinical context. The accompanying pancreatic-associated protein markers (LYVE1, REG1B, and TFF1) are also elevated, reinforcing a cancer signal rather than a benign condition. Overall biomarker pattern is highly consistent with pancreatic cancer.
A3: 2 | B3: 0 | C3: 86 | D3: CA19-9 is low/within normal range (30), which argues against pancreatic cancer. The other markers (LYVE1 very low, REG1B modest, TFF1 elevated) do not form a strong pancreatic-cancer pattern without a CA19-9 rise; overall biomarker profile is more consistent with non-malignant/pancreatic inflammation-related changes than cancer.
A4: 3 | B4: 1 | C4: 99 | D4: CA19-9 is extremely elevated (11740), far above typical benign elevations and highly suggestive of pancreatic malignancy in this evaluation context. Additional pancreatic-associated markers (REG1B, TFF1, LYVE1) are also markedly elevated, supporting a cancer profile. Normal creatinine reduces the likelihood that CA19-9 is falsely elevated due to renal impairment.
A5: 4 | B5: 0 | C5: 92 | D5: CA19-9 is very low/normal (6.71), which argues strongly against pancreatic cancer. The additional markers provided (LYVE1, REG1A/REG1B, TFF1) do not show a pattern that outweighs the low CA19-9; creatinine is low and unlikely to be falsely elevating tumor markers. Overall biomarker profile is more consistent with no pancreatic cancer.
A6: 5 | B6: 1 | C6: 97 | D6: CA19-9 is extremely elevated (1621), which is highly suggestive of pancreatic malignancy in the appropriate clinical context. Although creatinine is markedly high (renal dysfunction can increase CA19-9), the magnitude of elevation plus an age typical for pancreatic cancer supports cancer as the most likely explanation. The additional protein markers (elevated TFF1/REG family) are also more consistent with pancreatic tumor-associated signatures than with a purely benign process.
A7: 6 | B7: 1 | C7: 96 | D7: CA19-9 is markedly elevated (538), which is strongly suggestive of pancreatic malignancy in this age group. The associated biomarker panel shows very high TFF1 and elevated REG1B/REG1A, a pattern consistent with pancreatic cancer rather than benign disease. Normal creatinine reduces the likelihood that CA19-9 is falsely elevated from renal impairment.
A8: 7 | B8: 0 | C8: 92 | D8: CA19-9 is very low (6.9), which argues strongly against pancreatic cancer in a typical secretor. Other provided biomarkers do not show a clear malignant pattern sufficient to outweigh the low CA19-9, and renal function (creatinine ~0.95) is normal, reducing concern for CA19-9 distortion from kidney impairment. Overall profile is more consistent with non-cancer.
A9: 8 | B9: 0 | C9: 71 | D9: CA19-9 is within/near normal range (~31 U/mL; typically concerning when clearly elevated, e.g., >37 and especially much higher). Creatinine is normal, reducing concern for renal-related marker distortion. Although LYVE1/REG1B/TFF1 show some elevation, the absence of a clearly elevated CA19-9 makes pancreatic cancer less likely overall in this profile.
A10: 9 | B10: 1 | C10: 86 | D10: CA19-9 is markedly elevated (468), which is strongly suspicious for pancreatic malignancy. The supporting protein biomarkers are also very high (notably TFF1 ~2207 and elevated REG1A/REG1B), a pattern more consistent with pancreatic cancer-associated signatures than benign disease. Although the patient is young and creatinine is very high (which can confound CA19-9), the magnitude and multi-marker concordance still favor cancer.
A11: 10 | B11: 1 | C11: 72 | D11: CA19-9 is elevated (66; above typical 37 cutoff) and there is a strongly abnormal multi-marker pattern with very high TFF1 and elevated REG1B/REG1A, which together are more consistent with pancreatic malignancy than benign disease. Creatinine is normal, making a renal-related artifact less likely.
A12: 11 | B12: 0 | C12: 74 | D12: CA19-9 is only mildly elevated (50) and can rise with benign biliary/inflammatory conditions; age is relatively young for pancreatic cancer. The protein markers (LYVE1, REG1B, TFF1, REG1A) do not show a strongly cancer-typical pattern with markedly elevated CA19-9, and creatinine is normal, reducing concern for confounding renal retention. Overall profile is more consistent with non-malignant or low-likelihood disease than pancreatic cancer.
A13: 12 | B13: 0 | C13: 78 | D13: CA19-9 is low/within normal range (22), which argues against pancreatic cancer. Creatinine is normal, reducing concern for CA19-9 distortion from renal dysfunction. Although REG1B/TFF1 appear elevated, in the setting of a normal CA19-9 and no other supportive clinical signals, the overall biomarker pattern is more consistent with non-malignant pancreatic/inflammatory changes than cancer.
... A64: 63 | B64: 1 | C64: 78 | D64: CA19-9 is clearly elevated (114.8), which supports pancreatic malignancy in the right context. In addition, multiple pancreatic-associated protein biomarkers (REG1B, TFF1, LYVE1) are markedly elevated, a pattern more consistent with pancreatic cancer signatures than with normal findings. Creatinine is elevated but does not by itself explain the combined strong multi-marker elevation.

Sheet classify2
A1: Patient | B1: cancer_prediction | C1: confidence | D1: reasoning
A2: 1 | B2: 1 | C2: 93 | D2: CA19-9 is markedly elevated (422), which strongly supports pancreatic malignancy in the appropriate clinical context. The accompanying panel shows substantially elevated LYVE1, REG1B, and especially TFF1, a biomarker pattern commonly associated with pancreatic cancer rather than benign disease. Age (68) also increases pretest probability.
A3: 2 | B3: 0 | C3: 82 | D3: CA19-9 is low/within typical non-cancer range (30), which argues against pancreatic cancer. REG1B is modest and LYVE1 is very low without a concurrent CA19-9 elevation, reducing likelihood of malignancy. Overall biomarker pattern is not characteristic of pancreatic cancer despite elevated TFF1.
A4: 3 | B4: 1 | C4: 99 | D4: CA19-9 is extremely elevated (11740), far above typical benign ranges, strongly suggesting pancreatic malignancy. Creatinine is normal, making renal impairment unlikely to explain the CA19-9 level. The accompanying biomarker profile (elevated LYVE1/REG1B/TFF1 and high REG1A) is also consistent with pancreatic cancer signatures in evaluated panels.
A5: 4 | B5: 0 | C5: 86 | D5: CA19-9 is very low (6.71), which argues strongly against pancreatic cancer in this screening context. Other markers (LYVE1 low, REG1A modest, TFF1 elevated) are not sufficiently specific to outweigh a normal CA19-9, so overall profile is more consistent with non-cancer.
A6: 5 | B6: 1 | C6: 96 | D6: CA19-9 is extremely elevated (1621), which is strongly suggestive of pancreatic malignancy in the appropriate clinical context. Although creatinine is markedly high and renal dysfunction can increase CA19-9, levels this high are more consistent with cancer. Supporting protein biomarkers (very high TFF1 and elevated REG1A/REG1B) further align with a pancreatic cancer profile.
A7: 6 | B7: 1 | C7: 97 | D7: CA19-9 is markedly elevated (538), which is strongly suggestive of pancreatic malignancy when renal function is normal (creatinine 0.77 reduces risk of false elevation). Additional pancreatic cancer–associated markers (LYVE1, REG1B, TFF1) are substantially elevated, supporting a cancer profile rather than benign disease.
A8: 7 | B8: 0 | C8: 86 | D8: CA19-9 is very low (6.9), which is strongly against pancreatic cancer in most cases. Creatinine is normal, reducing concern for biomarker distortion from renal dysfunction. The additional markers (LYVE1, REG1B, TFF1, REG1A) do not show a pattern suggestive of malignancy without an elevated CA19-9, so overall findings favor no pancreatic cancer.
A9: 8 | B9: 0 | C9: 73 | D9: CA19-9 is within the normal range (~<37 U/mL), which lowers suspicion for pancreatic cancer. Creatinine is normal, reducing concern for CA19-9 distortion from renal impairment. While REG1B and TFF1 show elevation and could be associated with pancreatic pathology/inflammation, the absence of an elevated CA19-9 and lack of other strong malignant-pattern markers makes pancreatic cancer less likely overall.
A10: 9 | B10: 0 | C10: 63 | D10: Although CA19-9 is markedly elevated (468.3), the patient is very young (29) and has severe renal dysfunction (creatinine 280.488), which can falsely raise CA19-9 due to reduced clearance/cholestasis. The additional protein biomarkers (LYVE1, REG1B, REG1A) are not strongly in a cancer-consistent pattern, and TFF1 is only moderately elevated. Overall this profile is more consistent with non-malignant elevation of CA19-9 than pancreatic cancer.
A11: 10 | B11: 1 | C11: 74 | D11: CA19-9 is elevated (66; above typical 37 cutoff), and the cancer-associated protein panel shows markedly high TFF1 with elevated REG1B/REG1A, a pattern more consistent with pancreatic malignancy than benign conditions; normal creatinine makes a false CA19-9 elevation from renal impairment less likely.
A12: 11 | B12: 0 | C12: 72 | D12: CA19-9 is only mildly elevated (50) and can rise with benign biliary/pancreatic inflammation; age is relatively young for pancreatic cancer. Creatinine is normal, reducing concern for false elevation from renal impairment. The protein marker pattern (very high REG1A with elevated REG1B/TFF1 and moderate LYVE1) is more consistent with benign/regenerative/inflammatory pancreatic changes than a strong pancreatic cancer signature.
A13: 12 | B13: 0 | C13: 74 | D13: CA19-9 is low/within typical non-malignant range (22), which argues against pancreatic cancer. Creatinine is normal, reducing concern for CA19-9 distortion from renal impairment. The other protein markers are not strongly suggestive of a clear pancreatic cancer pattern in the absence of elevated CA19-9, so overall cancer is unlikely.
... A64: 63 | B64: 1 | C64: 78 | D64: CA19-9 is elevated (114.8; above typical cutoff ~37) and REG1B is markedly high, a pattern associated with pancreatic malignancy. Although age is relatively young and creatinine is elevated (which can sometimes confound markers), the combined biomarker profile (CA19-9 + REG family proteins) favors pancreatic cancer over benign causes.

Sheet classify3
A1: Patient | B1: cancer_prediction | C1: confidence | D1: reasoning
A2: 1 | B2: 1 | C2: 96 | D2: CA19-9 is markedly elevated (422), which is strongly suggestive of pancreatic malignancy in the appropriate clinical context. The accompanying protein biomarker pattern (very high LYVE1, REG1B, and TFF1) is consistent with a pancreatic cancer-associated signature rather than normal/benign levels. Overall biomarker burden strongly favors pancreatic cancer.
A3: 2 | B3: 0 | C3: 78 | D3: CA19-9 is within the normal/low range (~30), which argues against pancreatic cancer in many cases. The additional protein markers (LYVE1 very low, REG1B moderate, TFF1 elevated) do not form a strongly cancer-typical pattern without a concomitant CA19-9 rise, and creatinine is not elevated (reducing concern for CA19-9 distortion from renal dysfunction). Overall profile is more consistent with non-malignant/inflammatory variation than pancreatic cancer.
A4: 3 | B4: 1 | C4: 99 | D4: CA19-9 is extremely elevated (11740), far above typical benign elevations, strongly indicating pancreatic malignancy. Age 66 increases baseline risk, and creatinine is normal so the CA19-9 rise is unlikely due to renal impairment. Additional pancreatic-associated protein markers (elevated REG1B/TFF1/LYVE1) further support a cancer profile.
A5: 4 | B5: 0 | C5: 92 | D5: CA19-9 is very low (6.71, well below typical cancer-associated elevations). Other listed markers (LYVE1, REG1A/REG1B, TFF1) do not show a pattern strongly suggestive of pancreatic cancer in the absence of CA19-9 elevation. Overall biomarker profile is more consistent with no pancreatic cancer.
A6: 5 | B6: 1 | C6: 96 | D6: CA19-9 is extremely elevated (1621), a level highly suggestive of pancreatic malignancy in the right context. Although creatinine is markedly high (possible renal dysfunction can inflate CA19-9), the CA19-9 magnitude plus markedly abnormal pancreatic-associated proteins (very high TFF1 and elevated REG family markers) supports pancreatic cancer rather than benign elevation alone.
A7: 6 | B7: 1 | C7: 97 | D7: CA19-9 is markedly elevated (538), which strongly supports pancreatic malignancy in the appropriate clinical context. The accompanying biomarker panel shows very high TFF1 and elevated REG1B/REG1A, a pattern consistent with pancreatic tumor-associated secretory changes rather than normal variation. Renal function (creatinine 0.77) is normal, reducing the likelihood of a false CA19-9 elevation from impaired clearance.
A8: 7 | B8: 0 | C8: 91 | D8: CA19-9 is very low (6.9), which argues strongly against pancreatic cancer in this context. Creatinine is normal, reducing concern for biomarker distortion from renal dysfunction. The additional protein markers (LYVE1, REG1B, TFF1, REG1A) do not show a pattern suggestive of pancreatic cancer overriding the very low CA19-9.
A9: 8 | B9: 0 | C9: 72 | D9: CA19-9 is within/near the normal range (~31) and does not suggest pancreatic malignancy. Creatinine is normal, reducing concern for biomarker distortion from renal dysfunction. While REG1B, TFF1, and LYVE1 show some elevation, the absence of a clearly elevated CA19-9 and lack of a strongly malignant biomarker pattern overall makes pancreatic cancer less likely than benign/inflammatory processes.
A10: 9 | B10: 1 | C10: 82 | D10: CA19-9 is markedly elevated (468.3), which strongly raises suspicion for pancreatic malignancy. The accompanying panel shows very high TFF1 and REG1B/REG1A with elevated LYVE1, a biomarker pattern more consistent with pancreatic cancer-associated pancreatic injury than a benign state. Although the patient is young (29) and creatinine is high (possible renal impairment can inflate CA19-9), the degree of CA19-9 elevation plus the multi-marker elevation supports cancer as the more likely explanation.
A11: 10 | B11: 1 | C11: 74 | D11: CA19-9 is elevated (66, above typical normal ~<37). In addition, the pancreatic protein markers REG1B and REG1A are markedly elevated and TFF1 is extremely high, a pattern more consistent with pancreatic malignancy-associated biomarker elevation than benign variation; normal creatinine makes renal-related marker distortion less likely.
A12: 11 | B12: 0 | C12: 62 | D12: CA19-9 is only mildly elevated (50) and can be raised in benign biliary/pancreatic inflammation; creatinine is normal, reducing concern for non-specific elevation. The reported protein markers (LYVE1, REG1B, TFF1, REG1A) do not show a pattern strongly suggestive of pancreatic cancer here, so overall findings fit better with no cancer than with malignancy.
A13: 12 | B13: 0 | C13: 76 | D13: CA19-9 is low/within normal range (22), which argues against pancreatic cancer. Creatinine is normal, reducing concern for falsely altered marker levels from renal dysfunction. While LYVE1/REG1B/TFF1 show no clear extreme elevation suggestive of a strong cancer signal, the overall biomarker pattern is more consistent with non-cancer than pancreatic malignancy.
... A64: 63 | B64: 1 | C64: 78 | D64: CA19-9 is clearly elevated (114.8, above typical cutoff ~37), supporting pancreatic malignancy risk. REG1B and TFF1 are also elevated, consistent with pancreatic tumor-associated/ductal injury markers. Although creatinine is high (140) which can contribute to CA19-9 elevation, the combination of multiple elevated pancreatic biomarkers makes cancer more likely than benign causes.

Sheet classify4
A1: Patient | B1: cancer_prediction | C1: confidence | D1: reasoning
A2: 1 | B2: 1 | C2: 93 | D2: CA19-9 is markedly elevated (422), strongly suggestive of pancreatic malignancy in this context. Additional tumor-associated protein markers (LYVE1, REG1B, TFF1) are elevated, reinforcing a cancer pattern rather than benign disease; creatinine is not elevated enough to explain CA19-9 by renal impairment.
A3: 2 | B3: 0 | C3: 78 | D3: CA19-9 is 30 (within/near normal range and not suggestive of pancreatic cancer). LYVE1 is very low and REG1B is only mildly elevated, while REG1A is 0; this pattern is not strongly consistent with the elevated multi-marker signatures typically seen in pancreatic cancer. Overall biomarker profile supports no cancer detected.
A4: 3 | B4: 1 | C4: 99 | D4: CA19-9 is extremely elevated (11740), far above typical benign or pancreatitis ranges and highly suggestive of pancreatic malignancy; creatinine is normal so this is unlikely to be a renal clearance artifact. Additional tumor-associated proteins (LYVE1/REG1B/TFF1) are also elevated, further supporting pancreatic cancer.
A5: 4 | B5: 0 | C5: 86 | D5: CA19-9 is very low (6.71), which argues strongly against pancreatic cancer. LYVE1 is also very low and does not suggest malignancy. Although REG1B and TFF1 appear elevated, these markers can rise with benign pancreatic/inflammatory conditions and are less specific without a concurrent CA19-9 increase; overall biomarker pattern is more consistent with no cancer.
A6: 5 | B6: 1 | C6: 97 | D6: CA19-9 is extremely elevated (1621), which is highly suggestive of pancreatic malignancy in the right clinical context. Although creatinine is very high (renal dysfunction can raise CA19-9), the magnitude of elevation plus supportive cancer-associated protein marker pattern (elevated LYVE1/REG1B and abnormal TFF1) makes pancreatic cancer more likely than a benign cause alone.
A7: 6 | B7: 1 | C7: 96 | D7: CA19-9 is markedly elevated (538), far above typical benign ranges and strongly suggestive of pancreatic malignancy. Additional pancreatic cancer–associated protein markers (notably very high TFF1 and elevated REG1B/LYVE1) further support a cancer profile rather than non-malignant disease; creatinine is normal so renal impairment is unlikely to explain the CA19-9 elevation.
A8: 7 | B8: 0 | C8: 92 | D8: CA19-9 is very low (6.9), which argues strongly against pancreatic cancer. Creatinine is normal, reducing concern for false CA19-9 elevation/renal confounding. The other markers (LYVE1, REG1B, TFF1, REG1A) do not show a pattern suggestive of malignancy in the setting of a normal CA19-9.
A9: 8 | B9: 0 | C9: 72 | D9: CA19-9 is within the normal/near-normal range (~31) and creatinine is normal, reducing concern for spurious CA19-9 elevation. While REG1B/TFF1/LYVE1 are present, there is no strong CA19-9 elevation to support pancreatic cancer; overall biomarker pattern is more consistent with no malignancy.
A10: 9 | B10: 1 | C10: 78 | D10: CA19-9 is markedly elevated (468), which strongly raises suspicion for pancreatic malignancy. The panel proteins (notably very high TFF1 and elevated REG family markers) are also consistent with a cancer-associated secretory pattern. Although creatinine is very high and renal dysfunction can inflate CA19-9 (reducing specificity), the degree of CA19-9 elevation plus the multi-marker pattern still favors pancreatic cancer over benign causes in this record.
A11: 10 | B11: 0 | C11: 63 | D11: CA19-9 is only mildly elevated (66) and can rise with benign biliary/pancreatic inflammation; creatinine is normal, reducing concern for renal-related marker distortion. The additional biomarkers (LYVE1, REG1A/REG1B, TFF1) do not show a clearly extreme malignant pattern in this context, so overall findings fit better with a non-cancer process than definite pancreatic cancer.
A12: 11 | B12: 0 | C12: 73 | D12: CA19-9 is only mildly elevated (50) and not in the typically higher ranges often seen with pancreatic cancer; creatinine is normal (less likely false CA19-9 elevation from renal impairment). The protein marker pattern shows very high REG1A with elevated REG1B/TFF1, which can be seen in benign pancreatic/inflammatory conditions and is not a strong cancer-specific signature here. Overall profile favors non-malignant pancreatic disease over pancreatic cancer.
A13: 12 | B13: 0 | C13: 78 | D13: CA19-9 is low/within typical non-cancer range (22), not suggestive of pancreatic malignancy. Creatinine is normal, reducing concern for biomarker distortion from renal dysfunction. The provided protein markers (LYVE1/REG1B/TFF1/REG1A) do not show a clear cancer-indicative pattern here, so overall findings favor no pancreatic cancer.
... A64: 63 | B64: 1 | C64: 74 | D64: CA19-9 is clearly elevated (114.8; above typical benign range), and multiple pancreatic-associated protein markers (LYVE1, REG1B, TFF1) are concurrently high, which together increases likelihood of pancreatic malignancy rather than an isolated false-positive CA19-9. Elevated creatinine could contribute to biomarker elevation but is unlikely to explain the combined multi-marker pattern.

Sheet classify5
A1: Patient | B1: cancer_prediction | C1: confidence | D1: reasoning
A2: 1 | B2: 1 | C2: 93 | D2: CA19-9 is markedly elevated (422), which is strongly suggestive of pancreatic malignancy in this evaluation context. The accompanying biomarker pattern (very high TFF1, REG1B and elevated LYVE1) is consistent with pancreatic cancer-associated signatures rather than normal/benign ranges.
A3: 2 | B3: 0 | C3: 78 | D3: CA19-9 is low/near-normal (30), which argues against pancreatic cancer. REG1B is only mildly elevated and LYVE1 is very low; the overall biomarker pattern does not show the typical strong elevations seen in pancreatic cancer. No additional clinical red flags are provided.
